#!/usr/bin/env python3
import os, time, logging
from typing import List

import yaml
from celery import Celery
from celery.signals import task_failure


class TransientNetworkError(Exception):
    pass

with open(os.getenv('config', 'configs/local.yaml'), 'r') as f:
   config = yaml.safe_load(f)

logger = logging.getLogger(__name__)
#logging.basicConfig(level=logging.INFO)
app = Celery('tasks', broker=config["redis"]["broker"], result_backend=config["redis"]["result_backend"])
# app.config_from_object('celeryconfig')


@task_failure.connect
def handle_task_failure(sender=None, task_id=None, exception=None, args=None, **kwargs):
    print(f"üí£ Task {sender.name}({task_id}) failed: {exception} with args: {args}")


@app.task(bind=True)
def process_document(self, filepaths: List[str]):
    try:
        logger.info(f"üìÑ Processing file(s): {filepaths}")
        #if "network" in file_path:
        #    raise TransientNetworkError("üåê Simulated network error")

        #if "invalid" in filepaths:
        #    raise ValueError("‚ùå Irrecoverable format error")

        size_bytes = 0
        for p in filepaths:
            time.sleep(10)
            size_bytes += os.path.getsize(p)

        print("‚úÖ Done.")
        return {"status": "completed", "count": len(filepaths), "size_bytes": size_bytes }

    except TransientNetworkError as e:
        logger.error(f"‚ö†Ô∏è Transient error: {e}, retrying...")
        raise self.retry(exc=e)

    except Exception as e:
        logger.exception(f"‚ùå Fatal error: {e}")
        raise e  # don't auto retry
